




































235/235 [==============================] - ETA: 0s - loss: 0.5755 - accuracy: 0.9035
C:\Users\Lucas\AppData\Local\Programs\Python\Python311\Lib\site-packages\keras\src\engine\training.py:3079: UserWarning: You are saving your model as an HDF5 file via `model.save()`. This file format is considered legacy. We recommend using instead the native Keras format, e.g. `model.save('my_model.keras')`.
  saving_api.save_model(
INFO:tensorflow:Assets written to: C:\Users\Lucas\Documents\GitHub\LucHalt_TFE21-2_deepLearning\code\wandb\run-20231104_170233-zhje7ocy\files\model-best\assets

235/235 [==============================] - ETA: 0s - loss: 0.5755 - accuracy: 0.9035INFO:tensorflow:Assets written to: C:\Users\Lucas\Documents\GitHub\LucHalt_TFE21-2_deepLearning\code\wandb\run-20231104_170233-zhje7ocy\files\model-best\assets
Traceback (most recent call last):
  File "C:\Users\Lucas\AppData\Local\Temp\ipykernel_12136\3820709640.py", line 110, in sweep_train
    wandb.log(data={"val_accuracy": val_accuracy}, step=epoch)
                                    ^^^^^^^^^^^^
NameError: name 'val_accuracy' is not defined
235/235 [==============================] - 87s 359ms/step - loss: 0.5755 - accuracy: 0.9035 - val_loss: 0.2679 - val_accuracy: 0.9699